Traceback (most recent call last):
  File "C:\Users\aparn\anaconda3\envs\opened\Lib\site-packages\jupyter_cache\executors\utils.py", line 58, in single_nb_execution
    executenb(
  File "C:\Users\aparn\anaconda3\envs\opened\Lib\site-packages\nbclient\client.py", line 1305, in execute
    return NotebookClient(nb=nb, resources=resources, km=km, **kwargs).execute()
           ^^^^^^^^^^^^^^^^^^^^^^^^^^^^^^^^^^^^^^^^^^^^^^^^^^^^^^^^^^^^^^^^^^^^^
  File "C:\Users\aparn\anaconda3\envs\opened\Lib\site-packages\jupyter_core\utils\__init__.py", line 173, in wrapped
    return loop.run_until_complete(inner)
           ^^^^^^^^^^^^^^^^^^^^^^^^^^^^^^
  File "C:\Users\aparn\anaconda3\envs\opened\Lib\asyncio\base_events.py", line 654, in run_until_complete
    return future.result()
           ^^^^^^^^^^^^^^^
  File "C:\Users\aparn\anaconda3\envs\opened\Lib\site-packages\nbclient\client.py", line 705, in async_execute
    await self.async_execute_cell(
  File "C:\Users\aparn\anaconda3\envs\opened\Lib\site-packages\nbclient\client.py", line 1058, in async_execute_cell
    await self._check_raise_for_error(cell, cell_index, exec_reply)
  File "C:\Users\aparn\anaconda3\envs\opened\Lib\site-packages\nbclient\client.py", line 914, in _check_raise_for_error
    raise CellExecutionError.from_cell_and_msg(cell, exec_reply_content)
nbclient.exceptions.CellExecutionError: An error occurred while executing the following cell:
------------------
class KITT:
def __init__(self, model, color):
self.model = model
self.color = color
self.is_engine_on = False
------------------


[1;36m  Cell [1;32mIn[1], line 2[1;36m[0m
[1;33m    def __init__(self, model, color):[0m
[1;37m    ^[0m
[1;31mIndentationError[0m[1;31m:[0m expected an indented block after class definition on line 1


